Workbook

Sheet Summary
A1: Destination / Option | B1: Trip Character | C1: Ground Nights | D1: Flight Nights | E1: Low Total (USD) | F1: Mid Total (USD) | G1: High Total (USD) | H1: Cost/Night Mid | I1: Cost Confidence | J1: Logistics Friction | K1: Weather Risk July | L1: Cultural Depth | M1: Teen Appeal | N1: Key Strength | O1: Key Weakness
A2: Greece — Opt 1 (Cyclades) | B2: Ancient city + two-island Cyclades | C2: 9 | D2: 1 | E2: =Greece_Costs!E23 | F2: =Greece_Costs!F23 | G2: =Greece_Costs!G23 | H2: =Greece_Costs!F23/C2 | I2: Medium | J2: Medium-High | K2: High (heat + meltemi) | L2: Highest | M2: High | N2: Most iconic and memorable trip | O2: Transfer drag; heat; Santorini crowds
A3: Greece — Opt 2 (Crete) | B3: Crete beaches + history + Athens day | C3: 9 | D3: 1 | E3: =Greece2_Costs!E21 | F3: =Greece2_Costs!F21 | G3: =Greece2_Costs!G21 | H3: =Greece2_Costs!F21/C3 | I3: Medium | J3: Medium | K3: Moderate (heat; car on narrow roads) | L3: Highest | M3: High | N3: Most historically rich; car freedom; no ferry anxiety | O3: No Santorini caldera view; car adds rental/fuel complexity
A4: Bavaria + Salzburg | B4: Rail-based Alpine and city tour | C4: 9 | D4: 1 | E4: =Bavaria_Costs!E28 | F4: =Bavaria_Costs!F28 | G4: =Bavaria_Costs!G28 | H4: =Bavaria_Costs!F28/C4 | I4: Medium-High | J4: Medium | K4: Moderate (mountain weather) | L4: High | M4: Very High | N4: Most balanced and stress-light | O4: Weather-sensitive mountain days; over-design risk
A5: Bavaria — Opt 2 (Cities & Castles) | B5: Cities and castles (Munich-Berchtesgaden-Salzburg) | C5: 9 | D5: 1 | E5: =Bavaria2_Costs!E27 | F5: =Bavaria2_Costs!F27 | G5: =Bavaria2_Costs!G27 | H5: =Bavaria2_Costs!F27/C5 | I5: Medium-High | J5: Low-Medium | K5: Moderate (mountain weather) | L5: High | M5: Very High | N5: Neuschwanstein; Hallstatt; castle-focused; less hiking | O5: No alpine village base; Mittenwald removed; similar cost to Opt 1
A6: St. Lucia — Option A (All-Inclusive) | B6: Tropical adventure + resort base | C6: 10 | D6: 0 | E6: =StLucia_Costs!E26 | F6: =StLucia_Costs!F26 | G6: =StLucia_Costs!G26 | H6: =StLucia_Costs!F26/C6 | I6: Medium | J6: Low | K6: Moderate-High (hurricane season) | L6: Moderate | M6: High | N6: Full 10 nights; easy logistics; all-in pricing | O6: Lower cultural depth; lodging cost dominates
A7: St. Lucia — Option B (Villa + Bay Gardens) | B7: Tropical adventure + villa/split | C7: 10 | D7: 0 | E7: =StLucia_Costs!E27 | F7: =StLucia_Costs!F27 | G7: =StLucia_Costs!G27 | H7: =StLucia_Costs!F27/C7 | I7: Medium | J7: Medium | K7: Moderate-High (hurricane season) | L7: Moderate | M7: High | N7: Best value; most local feel | O7: One transfer mid-trip; more daily decisions

Sheet Greece_Itinerary
A1: Day | B1: Date | C1: Location | D1: Overnight | E1: Morning | F1: Afternoon | G1: Evening | H1: Transport | I1: Travel Time | J1: Book Ahead | K1: Weather Sensitive | L1: Backup Option | M1: Est. Daily Cost (Family USD) | N1: Notes
A2: 1 | B2: Sat Jul 11 | C2: DC → Athens | D2: In-flight | E2: Airport departure | F2: Transatlantic flight | G2: In-flight | H2: IAD nonstop or via FRA/IST | I2: Overnight | J2: Y | K2: N | L2: None | M2: 0 | N2: Europe clock begins on flight night
A3: 2 | B3: Sun Jul 12 | C3: Athens | D3: Athens | E3: Arrive ATH; airport express train; hotel check-in | F3: Plaka walk; Anafiotika lanes; light lunch | G3: Rooftop dinner with Acropolis view | H3: Airport express train | I3: 40 min | J3: N | K3: N | L3: Pool/nap day | M3: 320 | N3: Keep light; absorb jet lag
A4: 3 | B4: Mon Jul 13 | C4: Athens | D4: Athens | E4: Acropolis at 8 am (timed entry required) | F4: Acropolis Museum; shaded lunch; siesta during peak heat | G4: Athens food tour or Monastiraki evening | H4: Local metro/taxi | I4: Local | J4: Y (Acropolis tickets) | K4: Y (heat) | L4: Museum first if very hot | M4: 420 | N4: Book Acropolis timed entry well in advance
A5: 4 | B5: Tue Jul 14 | C5: Athens → Naxos | D5: Naxos | E5: Blue Star ferry from Piraeus ~07:30 | F5: Arrive Naxos ~13:00; check in; Agios Georgios beach | G5: Sunset at the Portara; dinner in Chora | H5: Piraeus ferry | I5: 5.5 hrs | J5: Y | K5: Y (wind) | L5: Fly ATH–JNX if seas rough | M5: 530 | N5: Blue Star more wind-stable than Seajets; recommended for Piraeus–Naxos
A6: 5 | B6: Wed Jul 15 | C6: Naxos | D6: Naxos | E6: Mount Zas hike (start 6:30 am; 3–4 hrs RT; Zeus's Cave en route) | F6: Lunch in Filoti; taxi to Apeiranthos marble village | G6: Halki village; citron distillery tasting; dinner in Chora | H6: Bus or local taxi | I6: Half-day | J6: N | K6: Y (summit heat) | L6: Village loop without the summit hike | M6: 320 | N6: Hire taxi for village loop ~€80 half-day
A7: 6 | B7: Thu Jul 16 | C7: Naxos | D7: Naxos | E7: Half-day catamaran with snorkeling (departs Chora ~10 am) | F7: Plaka or Agia Anna beach | G7: Waterfront dinner in Naxos Town | H7: Boat; local bus | I7: Full morning | J7: Y | K7: Y (wind cancels boats) | L7: Pure beach day at Plaka if winds strong | M7: 520 | N7: Book catamaran 1–2 weeks ahead; best teen day on Naxos
A8: 7 | B8: Fri Jul 17 | C8: Naxos → Santorini | D8: Santorini | E8: Late beach swim; lunch in Chora | F8: Seajets fast ferry to Santorini (~1.5 hrs); check in to Imerovigli | G8: Skaros Rock sunset walk; dinner in Imerovigli | H8: Seajets | I8: 1.5 hrs | J8: Y | K8: Y (wind cancels Seajets) | L8: Blue Star backup or fly JNX–JTR | M8: 840 | N8: Book Seajets early; July Fridays fill fast
A9: 8 | B9: Sat Jul 18 | C9: Santorini | D9: Santorini | E9: Fira-to-Oia caldera hike (start 6:30 am; 10 km; ~3.5 hrs) | F9: Oia exploration; lunch; bus/taxi back | G9: Dinner in Imerovigli | H9: Walk + bus/taxi | I9: 3.5 hrs hiking | J9: N | K9: N | L9: Sleep in; taxi to Oia instead | M9: 580 | N9: Start at dawn; heat arrives fast; single best free activity in Greece
A10: 9 | B10: Sun Jul 19 | C10: Santorini | D10: Santorini | E10: Caldera catamaran tour (volcano + hot springs + Red Beach; ~5 hrs) | F10: Akrotiri archaeological site (€15/adult) | G10: Quiet caldera viewpoint dinner | H10: Catamaran + taxi | I10: Full day | J10: Y | K10: Y (boat cancels in wind) | L10: Akrotiri + Red Beach by land if seas rough | M10: 860 | N10: Akrotiri requires timed entry; book ahead
A11: 10 | B11: Mon Jul 20 | C11: Santorini → Athens | D11: Athens (airport area) | E11: Aegean Airlines morning flight to ATH (~50 min) | F11: Buffer afternoon in Athens; Stavros Niarchos or Syntagma stroll | G11: Early dinner; airport-area hotel (Sofitel Athens Airport) | H11: Domestic flight | I11: 50 min + transfer | J11: Y | K11: N | L11: Piraeus fast ferry as backup | M11: 490 | N11: Never put international departure at risk of a ferry delay
A12: 11 | B12: Tue Jul 21 | C12: Athens → DC | D12: At home | E12: Depart ATH | F12: Transatlantic home | G12: Arrive DC | H12: IAD nonstop or connecting | I12: Long-haul | J12: Y | K12: N | L12: None | M12: 0

Sheet Bavaria_Itinerary
A1: Day | B1: Date | C1: Location | D1: Overnight | E1: Morning | F1: Afternoon | G1: Evening | H1: Transport | I1: Travel Time | J1: Book Ahead | K1: Weather Sensitive | L1: Backup Option | M1: Est. Daily Cost (Family USD) | N1: Notes
A2: 1 | B2: Sat Jul 11 | C2: DC → Munich | D2: In-flight | E2: Airport departure | F2: Overnight transatlantic | G2: In-flight | H2: IAD nonstop (Lufthansa/United) | I2: ~8–10 hrs | J2: Y | K2: N | L2: None | M2: 0 | N2: Europe clock begins on flight night
A3: 2 | B3: Sun Jul 12 | C3: Munich | D3: Munich | E3: Arrive MUC ~9–10 am; S-Bahn to city; hotel check-in | F3: Marienplatz; Viktualienmarkt; Glockenspiel at noon | G3: Englischer Garten + Eisbach surfers; beer garden dinner | H3: S-Bahn S1/S8 | I3: 40–50 min | J3: N | K3: N | L3: Hotel pool/nap day | M3: 300 | N3: Eisbach river surfers free; a genuine teen highlight
A4: 3 | B4: Mon Jul 13 | C4: Munich | D4: Munich | E4: Deutsches Museum (4–5 hrs; €15/adult; €4.50/youth) | F4: BMW Welt (free) + BMW Museum (€10/adult) | G4: Hofbräuhaus or neighborhood beer garden | H4: Local U-Bahn | I4: Local | J4: N | K4: N | L4: Extra museum day; Alte Pinakothek alternative | M4: 380 | N4: BMW Welt is free and worth 2 hrs even for non-car people
A5: 4 | B5: Tue Jul 14 | C5: Munich → Mittenwald | D5: Mittenwald | E5: RB6 train to Mittenwald (1h 50m) | F5: Lüftlmalerei painted houses; Geigenbaumuseum (€5.50) | G5: Karwendelbahn cable car at sunset (optional; free under 15); dinner at Gasthof | H5: Bayern-Ticket + RB6 | I5: 1h 50m | J5: Y (Bayern-Ticket) | K5: N | L5: Slow afternoon if tired | M5: 400 | N5: Bayern-Ticket: 14yo rides free; 17yo = adult; €49/family
A6: 5 | B6: Wed Jul 15 | C6: Garmisch day trip | D6: Mittenwald | E6: RB train to Garmisch (~20 min); Partnach Gorge (€7/adult) | F6: Alpspitzbahn panorama (~€30/adult) or summer luge | G6: Return to Mittenwald; dinner | H6: Bayern-Ticket + regional train | I6: 20 min each way | J6: Y (Bayern-Ticket) | K6: N | L6: Easy valley walk in Garmisch if crowded | M6: 380 | N6: Partnach Gorge is underrated; good in heat
A7: 6 | B7: Thu Jul 16 | C7: Zugspitze or Leutaschklamm | D7: Mittenwald | E7: Check zugspitze.de webcam at 7 am. Clear → Zugspitze cogwheel + cable car (~$195 family). Socked in → Leutaschklamm gorge (€5/adult) | F7: Summit/gorge; Eibsee for swim if Zugspitze | G7: Lautersee or Ferchensee lake swim; dinner | H7: Bayern-Ticket + cogwheel train | I7: 1.5 hrs to summit from Garmisch | J7: Y (cable car tickets) | K7: Y (Zugspitze critical) | L7: Leutaschklamm + Lautersee lake swim (equally good day) | M7: 560 | N7: Never commit to Zugspitze without checking the webcam that morning
A8: 7 | B8: Fri Jul 17 | C8: Mittenwald → Berchtesgaden | D8: Berchtesgaden | E8: Mittenwald → Munich (1h 50m) + Munich → Berchtesgaden via Freilassing (2h 30m) | F8: Arrive mid-afternoon; Old Town walk; Royal Palace square | G8: Local dinner; early night | H8: Bayern-Ticket + regional rail | I8: 4h 20m total | J8: Y (Bayern-Ticket) | K8: N | L8: Break in Munich midway if needed | M8: 350 | N8: Longest luggage day; start ~9 am
A9: 8 | B9: Sat Jul 18 | C9: Königssee | D9: Berchtesgaden | E9: Bus 841 to Königssee dock (~10 min); first electric boat to St. Bartholomä — cliff-echo flugelhorn | F9: Hike Salet → Obersee (1.5 km; hidden glacial lake beyond the crowds) | G9: Return by boat; optional salt mine tour (€23/adult) | H9: Bus 841 + electric boat | I9: 10 min bus + 35 min each way boat | J9: Y (tickets at dock) | K9: Y (weather-dependent) | L9: Documentation Center Obersalzberg (indoor) | M9: 400 | N9: Take first morning boat; crowds build fast after 10 am
A10: 9 | B10: Sun Jul 19 | C10: Eagle's Nest + Salzburg | D10: Salzburg | E10: Bus 838; Documentation Center Obersalzberg (€6/adult); Kehlstein bus + tunnel elevator to Eagle's Nest (€36.10/adult; €21/youth; credit card only) | F10: Lunch at Kehlsteinhaus with Watzmann views | G10: Bus 840 Watzmann Express to Salzburg (50 min; ~€11/adult); Old Town evening stroll | H10: Bus 838 + Kehlstein bus + Bus 840 | I10: ~2 hrs activity + 50 min transfer | J10: Y (Eagle's Nest seasonal) | K10: Y (closes in cloud/wind) | L10: Königssee 2nd day or Ramsau valley hike | M10: 510 | N10: Eagle's Nest is historically moving; one of the best teen experiences on the trip
A11: 10 | B11: Mon Jul 20 | C11: Salzburg | D11: Salzburg | E11: Hohensalzburg Fortress funicular (€14.50/adult; €8.30/youth) | F11: Mirabell Gardens (free); Mozart's Birthplace (€13.50/adult); Getreidegasse stroll | G11: St. Peter Stiftskeller dinner (Europe's oldest restaurant; book ahead) | H11: Walk + local bus | I11: Local | J11: Y (restaurant) | K11: N | L11: Salzburg Card if doing 3+ paid sites | M11: 480 | N11: Compact walkable city; one of the most enjoyable low-effort days on this trip
A12: 11 | B12: Tue Jul 21 | C12: Salzburg → Munich → DC | D12: At home | E12: ÖBB Railjet 06:23 or 07:11 Salzburg → Munich (1h 28m; book seat reservation ~$30/pp, 3–4 wks ahead) | F12: S-Bahn S1/S8 to MUC airport (40 min); fly home | G12: Arrive DC | H12: Railjet + S-Bahn | I12: 2h 10m total | J12: Y (Railjet reservation) | K12: N | L12: None | M12: 170 | N12: Leave Salzburg by 7:15 am for a midday MUC departure

Sheet StLucia_Itinerary
A1: Day | B1: Date | C1: Location | D1: Overnight | E1: Morning | F1: Afternoon | G1: Evening | H1: Transport | I1: Travel Time | J1: Book Ahead | K1: Weather Sensitive | L1: Backup Option | M1: Est. Daily Cost (Family USD) | N1: Notes
A2: 1 | B2: Sat Jul 11 | C2: DC → St. Lucia | D2: Soufrière (B) / Coconut Bay (A) | E2: Drive to PHL; AA nonstop afternoon flight | F2: Arrive UVF ~6–7 pm; transfer to lodging | G2: Welcome dinner; early sleep | H2: PHL→UVF AA nonstop | I2: 4h 45m + 50 min transfer | J2: Y | K2: N | L2: Airport-area overnight if very late | M2: 320 | N2: Full 10 nights on island; same-day arrival is key advantage over Europe
A3: 2 | B3: Sun Jul 12 | C3: Soufrière | D3: Soufrière area | E3: Recovery day: villa pool or resort beach | F3: Light explore of Soufrière town; local lunch | G3: Piton-view dinner at local restaurant | H3: Walk / short taxi | I3: Local | J3: N | K3: Y (modest) | L3: Fully unprogrammed rest day | M3: 300 | N3: Protect this day from over-programming; the family needs to settle in
A4: 3 | B4: Mon Jul 13 | C4: Soufrière highlights | D4: Soufrière area | E4: Sulphur Springs drive-in volcano (~$10/pp + $5 mud bath) | F4: Toraille Waterfall ($5/pp) + Diamond Botanical Gardens + Mineral Baths ($10/adult) | G4: Local dinner in Soufrière | H4: Half-day driver (~$80 family) | I4: Half-day | J4: Y (driver) | K4: Y (mild) | L4: Swap with Tet Paul Nature Trail if energy low | M4: 430 | N4: Hire one driver for all three sites; best all-in-one iconic SL day
A5: 4 | B5: Tue Jul 14 | C5: Gros Piton hike | D5: Soufrière area | E5: 6:30 am pickup; Gros Piton summit hike (3.5–4 hrs RT; $50/pp trail fee + mandatory guide) | F5: Descend; lunch in Soufrière | G5: Pool recovery; early dinner | H5: Prebooked transfer | I5: 45 min to trailhead | J5: Y (guide required) | K5: Y (not in heavy rain) | L5: Tet Paul Nature Trail as lower-intensity alternative | M5: 440 | N5: Mandatory guide is a plus — they know the mountain and the flora
A6: 5 | B6: Wed Jul 15 | C6: Full-day catamaran | D6: Soufrière area | E6: Sea Spray 'Tout Bagay' or equivalent (~$140/adult; $80/child); departs Rodney Bay or Marigot Bay — Soufrière by sea; Sulphur Springs; Anse Cochon snorkel; open bar | F6: Continue cruise | G6: Return early evening; resort/villa dinner | H6: Prebooked catamaran | I6: Full day | J6: Y (1–2 wks ahead) | K6: Y (seas must be calm) | L6: Land-based Soufrière tour if seas rough | M6: 600 | N6: Book early; this is the best teen day on the island
A7: 6 | B7: Thu Jul 16 | C7: Rainforest zip-line | D7: Soufrière area | E7: Rainforest Adventures aerial tram + zip-line or Morne Coubaril Estate zip-line with cocoa tour (~$90–95/adult; $75/youth; min age 8; max 290 lbs) | F7: Villa or resort pool; afternoon downtime | G7: Casual dinner; pack for transfer | H7: Prebooked shuttle | I7: ~30–45 min | J7: Y | K7: Y (avoid lightning) | L7: Cocoa estate tour only if weather poor | M7: 440 | N7: Morne Coubaril combines zip-line with cocoa estate for cultural depth
A8: 7 | B8: Fri Jul 17 | C8: Soufrière → Rodney Bay | D8: Rodney Bay area | E8: Late breakfast; optional Tet Paul Nature Trail en route ($10/pp; easy 45-min; best dual-Piton panoramic view) | F8: Transfer north to Bay Gardens Beach Resort (~2 hrs by road or catamaran water taxi) | G8: Anse La Raye Fish Fry (local village; grilled lobster; breadfruit; rum punch; best food experience on island) | H8: Private taxi or catamaran water taxi | I8: 1.5–2 hrs | J8: Y (resort; Fish Fry) | K8: Y (mild) | L8: Skip Tet Paul; go straight north | M8: 400 | N8: Anse La Raye Fish Fry runs Friday and Saturday; arrange return transport ($30–40)
A9: 8 | B9: Sat Jul 18 | C9: Rodney Bay / Gros Islet | D9: Rodney Bay area | E9: Reduit Beach morning | F9: Pigeon Island National Park ($11/adult; Fort Rodney ruins; 18th-century cannons) | G9: Jambe de Bois café at Pigeon Island; marina sundowners | H9: Short taxi | I9: 15 min each way | J9: N | K9: Y (mild) | L9: Extra beach day at Reduit | M9: 300 | N9: Pigeon Island is underrated; teens like the fort ruins
A10: 9 | B10: Sun Jul 19 | C10: Snorkel + downtime | D10: Rodney Bay area | E10: Anse Chastanet snorkel (boat transfer ~$40/pp; turtles; parrotfish; reef drops off beach) | F10: Afternoon beach club; sunbeds; beach bar | G10: Sunset dinner at marina restaurant | H10: Boat or taxi | I10: 30–45 min to Anse Chastanet | J10: Optional | K10: Y (visibility-dependent) | L10: Pure resort beach day | M10: 380 | N10: Anse Chastanet reef is worth the transfer
A11: 10 | B11: Mon Jul 20 | C11: Reserve / flexible | D11: Rodney Bay area | E11: Weather makeup day or pure downtime — pre-book nothing | F11: Shopping; final swim; Castries market visit | G11: Farewell dinner; pack | H11: Local | I11: Local | J11: N | K11: Y | L11: Leave unplanned by design | M11: 270 | N11: Most important day to protect from pre-programming in July hurricane season
A12: 11 | B12: Tue Jul 21 | C12: St. Lucia → DC | D12: At home | E12: Resort shuttle to UVF (~1.5 hrs from Rodney Bay) | F12: AA nonstop UVF → PHL (~4h 45m); arrive ~7 pm; drive home | G12: At home | H12: Taxi + AA nonstop | I12: 1.5 hrs + 4h 45m | J12: Y | K12: N | L12: None | M12: 0

Sheet Bavaria2_Itinerary
A1: Day | B1: Date | C1: Location | D1: Overnight | E1: Morning | F1: Afternoon | G1: Evening | H1: Transport | I1: Travel Time | J1: Book Ahead | K1: Weather Sensitive | L1: Backup Option | M1: Est. Daily Cost (Family USD) | N1: Notes
A2: 1 | B2: Sat Jul 11 | C2: DC → Munich | D2: In-flight | E2: Airport departure | F2: Overnight transatlantic | G2: In-flight | H2: IAD nonstop (Lufthansa/United) | I2: ~8–10 hrs | J2: Y | K2: N | L2: None | M2: 0 | N2: Europe clock begins on flight night
A3: 2 | B3: Sun Jul 12 | C3: Munich | D3: Munich | E3: Arrive MUC ~9–10 am; S-Bahn to city; hotel check-in | F3: Marienplatz; Viktualienmarkt; Glockenspiel at noon | G3: Englischer Garten + Eisbach surfers; beer garden dinner | H3: S-Bahn S1/S8 | I3: 40–50 min | J3: N | K3: N | L3: Hotel pool/nap day | M3: 300 | N3: Eisbach river surfers free; a genuine teen highlight
A4: 3 | B4: Mon Jul 13 | C4: Munich | D4: Munich | E4: Deutsches Museum (4–5 hrs; €15/adult; €4.50/youth) | F4: BMW Welt (free) + BMW Museum (€10/adult) | G4: Hofbräuhaus or neighborhood beer garden | H4: Local U-Bahn | I4: Local | J4: N | K4: N | L4: Extra museum day; Alte Pinakothek alternative | M4: 380 | N4: BMW Welt is free and worth 2 hrs even for non-car people
A5: 4 | B5: Tue Jul 14 | C5: Neuschwanstein day trip | D5: Munich | E5: Regional train to Füssen (~2 hrs); bus to castle; timed interior tour | F5: Marienbrücke bridge view over gorge; optional Hohenschwangau Castle | G5: Return to Munich; dinner | H5: Bayern-Ticket + regional train | I5: 2 hrs each way | J5: Y (Neuschwanstein timed entry — book immediately) | K5: N | L5: Exterior + Marienbrücke if interior sells out | M5: 430 | N5: Book timed entry at tickets.hohenschwangau.de immediately; July sells out weeks ahead; under 18 free
A6: 5 | B6: Wed Jul 15 | C6: Munich | D6: Munich | E6: Nymphenburg Palace + formal gardens (~2 hrs; €15/adult) | F6: Olympic Park grounds (free) + Maximilianstrasse or Schwabing district | G6: Dinner in Munich | H6: U-Bahn + local | I6: Local | J6: N | K6: N | L6: Dachau Memorial if family interested in WWII history | M6: 350 | N6: Nymphenburg is a genuine royal palace; canals and formal gardens free even without entry
A7: 6 | B7: Thu Jul 16 | C7: Munich → Berchtesgaden | D7: Berchtesgaden | E7: Check out; regional train to Berchtesgaden (~2.5 hrs via Freilassing) | F7: Arrive mid-afternoon; Berchtesgaden Old Town walk; Royal Palace square | G7: Dinner at local Gasthof; early night | H7: Bayern-Ticket + regional rail | I7: ~2h 30m | J7: Y (Bayern-Ticket) | K7: N | L7: Break in Munich midway if needed | M7: 350 | N7: Bayern-Ticket covers the full day; straightforward connection
A8: 7 | B8: Fri Jul 17 | C8: Königssee | D8: Berchtesgaden | E8: Bus 841 to Königssee dock (~10 min); first electric boat to St. Bartholomä — cliff-echo flugelhorn | F8: Return by boat; afternoon rest or Old Town walk | G8: Dinner in Berchtesgaden | H8: Bus 841 + electric boat | I8: 10 min bus + 35 min each way boat | J8: Y (boat dock) | K8: Y (weather-dependent) | L8: Documentation Center Obersalzberg (indoor) | M8: 400 | N8: Take first morning boat; crowds build fast after 10 am
A9: 8 | B9: Sat Jul 18 | C9: Berchtesgaden → Salzburg | D9: Salzburg | E9: Bus 838; Documentation Center Obersalzberg (€6/adult); Kehlstein bus + tunnel elevator to Eagle's Nest (€36.10/adult; €21/youth) | F9: Berchtesgaden salt mine (~1.5 hrs; €23/adult) — core plan, not optional | G9: Bus 840 to Salzburg (~50 min); check in; light dinner | H9: Bus 838 + Bus 840 | I9: ~2 hrs activity + 50 min transfer | J9: Y (Eagle's Nest seasonal) | K9: Y (Eagle's Nest closes in cloud/wind) | L9: Salt mine only + travel to Salzburg if Eagle's Nest closed | M9: 520 | N9: Eagle's Nest historically moving; salt mine adds variety; Day 8 is full but manageable
A10: 9 | B10: Sun Jul 19 | C10: Salzburg | D10: Salzburg | E10: Hohensalzburg Fortress funicular (€14.50/adult; €8.30/youth) | F10: Mirabell Gardens (free); Mozart's Birthplace (€13.50/adult); Getreidegasse stroll | G10: St. Peter Stiftskeller dinner (Europe's oldest restaurant; book ahead) | H10: Walk + local bus | I10: Local | J10: Y (restaurant reservation) | K10: N | L10: Salzburg Card if doing 3+ paid sites | M10: 480 | N10: Compact walkable city; one of the most enjoyable low-effort days on this trip
A11: 10 | B11: Mon Jul 20 | C11: Hallstatt day trip | D11: Salzburg | E11: Regional train + bus to Hallstatt (~1.5 hrs each way); lake village walk; boat across the Hallstätter See | F11: Hallstatt salt mine museum (~1 hr); Beinhaus charnel house (unusual and memorable); lakeside lunch | G11: Return to Salzburg; evening Salzach riverside walk | H11: Regional train + bus | I11: 1.5 hrs each way | J11: N | K11: N | L11: Salzburg Museum der Moderne or Sound of Music tour instead | M11: 400 | N11: Arrive early to beat tour buses; Hallstatt is UNESCO-listed and unmistakably beautiful
A12: 11 | B12: Tue Jul 21 | C12: Salzburg → Munich → DC | D12: At home | E12: ÖBB Railjet 06:23 or 07:11 Salzburg → Munich (1h 28m; book seat reservation ~$30/pp, 3–4 wks ahead) | F12: S-Bahn S1/S8 to MUC airport (40 min); fly home | G12: Arrive DC | H12: Railjet + S-Bahn | I12: 2h 10m total | J12: Y (Railjet reservation) | K12: N | L12: None | M12: 170 | N12: Leave Salzburg by 7:15 am for a midday MUC departure

Sheet Greece2_Itinerary
A1: Day | B1: Date | C1: Location | D1: Overnight | E1: Morning | F1: Afternoon | G1: Evening | H1: Transport | I1: Travel Time | J1: Book Ahead | K1: Weather Sensitive | L1: Backup Option | M1: Est. Daily Cost (Family USD) | N1: Notes
A2: 1 | B2: Sat Jul 11 | C2: DC → Athens | D2: In-flight | E2: Airport departure | F2: Transatlantic flight | G2: In-flight | H2: IAD nonstop or via FRA/IST | I2: Overnight | J2: Y | K2: N | L2: None | M2: 0 | N2: Europe clock begins on flight night
A3: 2 | B3: Sun Jul 12 | C3: Athens → Chania | D3: Chania area | E3: Arrive ATH; connect to CHQ (Aegean ~50 min) | F3: Pick up rental car (CHQ airport); check in to Chania beach hotel | G3: Easy beach swim; dinner near hotel | H3: ATH→CHQ domestic + rental car pickup | I3: ~50 min flight + 20 min to hotel | J3: Y (Aegean domestic) | K3: N | L3: Relax at hotel on delayed arrival | M3: 360 | N3: Agia Marina / Stalos area; beach within walking distance of hotel
A4: 3 | B4: Mon Jul 13 | C4: Chania area | D4: Chania area | E4: Recovery beach morning; pool time | F4: Pool or beach; light lunch near hotel | G4: Chania Old Town + Venetian Harbor evening walk | H4: Short drive (~15 min) | I4: Local | J4: N | K4: N | L4: Full beach day | M4: 300 | N4: Chania Old Town is walkable; Venetian lighthouse is free
A5: 4 | B5: Tue Jul 14 | C5: West Crete | D5: Chania area | E5: Balos Lagoon (early start) — Kissamos ferry (~1.5 hrs) or drive to overlook | F5: Beach / swim at Balos or Falassarna (nearby alternative) | G5: Casual seafood dinner; return to hotel | H5: Rental car + Kissamos ferry | I5: ~1.5 hrs each way ferry | J5: Y (Kissamos ferry) | K5: Y (ferry cancels in wind) | L5: Falassarna beach by car — equally scenic; no ferry | M5: 480 | N5: Balos ferry fills in July — pre-book Kissamos ferry tickets
A6: 5 | B6: Wed Jul 15 | C6: Chania / villages | D6: Chania area | E6: Chania Old Town covered market + municipal market; morning shop | F6: Inland village drive (Vamos or Gavalochori); olive oil tasting | G6: Dinner in Chania | H6: Rental car | I6: ~30 min to villages | J6: N | K6: N | L6: Extra beach morning instead | M6: 280 | N6: Cretan olive oil tasting ~€20/pp; village kafeneion lunch is good value
A7: 6 | B7: Thu Jul 16 | C7: Imbros Gorge | D7: Chania area | E7: Imbros Gorge hike early start (~7 am; 8 km point-to-point; ~3.5 hrs) | F7: South coast lunch in Sfakia; swim at Sweetwater Beach (short boat from Sfakia) | G7: Low-key evening; early dinner; pack for drive east tomorrow | H7: Rental car (~45 min to trailhead) | I7: 45 min drive; 3.5 hr hike | J7: N | K7: Y (heat — start early) | L7: Beach day at Frangokastello instead | M7: 380 | N7: Gorge entry ~€5/pp; arrange taxi back from Sfakia (~€15 total)
A8: 7 | B8: Fri Jul 17 | C8: Chania → East Crete | D8: East Crete | E8: Check out; leisurely drive east on E75 (2.5–3 hrs total) | F8: Stop Rethymno Old Town — Venetian fortress (Fortezza), harbor lunch (~1 hr) | G8: Check in Agios Nikolaos; seaside harbor dinner | H8: Rental car (~2.5–3 hrs with stop) | I8: 2.5–3 hrs driving | J8: N | K8: N | L8: Skip Rethymno if tired; drive straight | M8: 400 | N8: Rethymno Fortezza ~€5 entry; worth 30–45 min; harbor seafood lunch
A9: 8 | B9: Sat Jul 18 | C9: East Crete — mythology day | D9: East Crete | E9: Knossos Palace early (opens 8 am; 1.5–2 hrs; book timed entry) | F9: Heraklion Archaeological Museum (2–3 hrs; excellent A/C midday) | G9: Heraklion harbor dinner; return to Agios Nikolaos (~1 hr) | H9: Rental car (~1 hr to Heraklion) | I9: ~1 hr each way | J9: Y (Knossos timed entry) | K9: Y (heat) | L9: Museum only if exhausted | M9: 490 | N9: Knossos + museum make the strongest possible Minoan double; don't split
A10: 9 | B10: Sun Jul 19 | C10: East Crete — island day | D10: East Crete | E10: Spinalonga boat trip from Elounda (~20 min crossing; 1.5 hrs on island) | F10: Beach or pool afternoon in Elounda | G10: Elounda or Agios Nikolaos harbor dinner | H10: Rental car + local boat | I10: 20 min boat each way | J10: Y (morning boat) | K10: Y (boat cancels in wind) | L10: Agios Nikolaos Archaeological Museum if seas rough | M10: 420 | N10: Spinalonga leper colony island is historically striking; book early boat to avoid crowds
A11: 10 | B11: Mon Jul 20 | C11: Crete → Athens | D11: Athens | E11: Return rental car at HER airport; fly HER→ATH (Aegean ~45 min) | F11: Check in Athens (Plaka or Koukaki area); afternoon rest | G11: Plaka walk + rooftop dinner with Acropolis view | H11: Rental car → HER + domestic flight | I11: ~45 min flight | J11: Y (Aegean; rental return timing) | K11: N | L11: Airport hotel if very late arrival | M11: 480 | N11: Return car before check-in to avoid Athens city parking fees
A12: 11 | B12: Tue Jul 21 | C12: Athens → DC | D12: At home | E12: Acropolis timed entry 7:30–9 am (FIRM; pre-book) OR relaxed hotel breakfast if flight too early | F12: Fly ATH→IAD (depart midday or afternoon) | G12: Arrive DC | H12: Taxi to ATH airport + transatlantic | I12: Long-haul | J12: Y (Acropolis — must pre-book) | K12: N | L12: Skip Acropolis if flight is early morning | M12: 170 | N12: Book Acropolis timed entry immediately; July 7:30 am slots sell out weeks ahead

Sheet Greece_Costs
A1: Category | B1: Item | C1: Unit Cost | D1: Qty | E1: Low (USD) | F1: Mid (USD) | G1: High (USD) | H1: Confidence | I1: Basis | J1: Source IDs
A2: Flights | B2: IAD→ATH round-trip economy × 4 | C2: $1,100–1,600/pp | D2: 4 | E2: 4000 | F2: 5200 | G2: 6400 | H2: Medium | I2: Live IAD–ATH searches May 2026; United nonstop ~$1,350–1,467 observed | J2: GR-FL
A3: Bags & Seats | B3: Economy bags + seat selection | C3: $90/pp RT | D3: 4 | E3: 200 | F3: 360 | G3: 560 | H3: Low | I3: Carrier-dependent; assume 1 checked bag/pp | J3: GR-FL
A4: Lodging | B4: Athens — 2 nights (arrival) | C4: $200–350/night | D4: 2 | E4: 400 | F4: 480 | G4: 700 | H4: Medium | I4: Plaka-area hotels (Athens Gate, Electra Metropolis range) | J4: GR-LO
A5: Lodging | B5: Naxos — 3 nights | C5: $150–375/night | D5: 3 | E5: 450 | F5: 750 | G5: 1125 | H5: Medium | I5: Iria Beach Art Hotel or similar mid-range | J5: GR-LO
A6: Lodging | B6: Santorini — 3 nights | C6: $300–800/night | D6: 3 | E6: 900 | F6: 1500 | G6: 2400 | H6: Medium | I6: Imerovigli/Firostefani caldera-adjacent; Oia center commands premium | J6: GR-LO
A7: Lodging | B7: Athens buffer — 1 night (airport area) | C7: $180–280/night | D7: 1 | E7: 180 | F7: 200 | G7: 280 | H7: Medium | I7: Sofitel Athens Airport or similar | J7: GR-LO
A8: Ferries | B8: Piraeus → Naxos (Blue Star mid or Seajets) | C8: $55–100/pp | D8: 4 | E8: 220 | F8: 300 | G8: 400 | H8: Medium-High | I8: Blue Star Ferries and Seajets direct schedules | J8: GR-FE
A9: Ferries | B9: Naxos → Santorini (Seajets fast ferry) | C9: $65–90/pp | D9: 4 | E9: 180 | F9: 260 | G9: 360 | H9: Medium-High | I9: Seajets Naxos–Santorini May 2026 fares | J9: GR-FE
A10: Internal Flight | B10: Santorini → Athens (Aegean Airlines domestic) | C10: $70–130/pp | D10: 4 | E10: 0 | F10: 480 | G10: 560 | H10: Medium | I10: Aegean Airlines; optional; ferry is the budget path back | J10: GR-DF
A11: Transfers | B11: Athens airport express train (round-trip) | C11: $18/pp RT | D11: 4 | E11: 40 | F11: 72 | G11: 72 | H11: High | I11: Proastiakos line; under-18 half price | J11: GR-TR
A12: Transfers | B12: Island taxis, buses, water taxis | C12: Estimate | D12: — | E12: 200 | F12: 350 | G12: 500 | H12: Low | I12: Naxos buses cheap; Santorini taxis expensive in July | J12: GR-TR
A13: Activities | B13: Acropolis timed entry (advance) | C13: €30/adult; €15/youth | D13: 4 | E13: 120 | F13: 170 | G13: 170 | H13: High | I13: Greek Ministry of Culture / hhticket.gr; €30 adult flat rate 2026 | J13: GR-AC
... A22: Travel Insurance | B22: Trip protection (ferries + weather) | C22: $80/pp | D22: 4 | E22: 200 | F22: 320 | G22: 500 | H22: Medium | I22: Recommended; covers ferry delays | J22: —
A23: TOTAL | E23: =SUM(E2:E22) | F23: =SUM(F2:F22) | G23: =SUM(G2:G22)

Sheet Bavaria_Costs
A1: Category | B1: Item | C1: Unit Cost | D1: Qty | E1: Low (USD) | F1: Mid (USD) | G1: High (USD) | H1: Confidence | I1: Basis | J1: Source IDs
A2: Flights | B2: IAD→MUC round-trip economy × 4 | C2: $950–1,600/pp | D2: 4 | E2: 3800 | F2: 4800 | G2: 6400 | H2: Medium-High | I2: Lufthansa and United IAD–MUC nonstop ~8h 10m; Icelandair via KEF lower | J2: BA-FL
A3: Bags & Seats | B3: Economy bags + seat selection | C3: $90/pp RT | D3: 4 | E3: 200 | F3: 300 | G3: 450 | H3: Low | I3: Carrier-dependent | J3: BA-FL
A4: Lodging | B4: Munich — 2 nights | C4: $200–450/night | D4: 2 | E4: 400 | F4: 600 | G4: 900 | H4: Medium | I4: Torbräu / NH Collection / Eurostars Grand Central range | J4: BA-LO
A5: Lodging | B5: Mittenwald — 3 nights | C5: $180–400/night | D5: 3 | E5: 540 | F5: 810 | G5: 1200 | H5: Medium | I5: Alpenhotel Rieger / Post Hotel range | J5: BA-LO
A6: Lodging | B6: Berchtesgaden — 2 nights | C6: $180–450/night | D6: 2 | E6: 360 | F6: 560 | G6: 900 | H6: Medium | I6: Hotel Edelweiss / Vier Jahreszeiten range | J6: BA-LO
A7: Lodging | B7: Salzburg — 2 nights (Festspiele premium applies) | C7: $250–600/night | D7: 2 | E7: 500 | F7: 750 | G7: 1200 | H7: Medium | I7: Hotel Wolf-Dietrich; book 5–6 months ahead for Festival dates | J7: BA-LO
A8: Rail | B8: Bayern-Ticket family × 4 days (14yo free; 17yo = adult; €49/day) | C8: €49/day | D8: 4 days | E8: 220 | F8: 231 | G8: 231 | H8: High | I8: DB official Bayern-Ticket; children 6–14 ride free with adult | J8: BA-RT
A9: Rail | B9: Salzburg → Munich Railjet + seat reservation | C9: ~$35/pp | D9: 4 | E9: 100 | F9: 140 | G9: 200 | H9: High | I9: ÖBB Railjet; book 3–4 weeks ahead with seat reservation | J9: BA-RT
A10: Rail | B10: MUC airport S-Bahn round-trip (2 × family day ticket) | C10: $70/family × 2 | D10: 2 trips | E10: 80 | F10: 140 | G10: 140 | H10: High | I10: MVV airport day ticket | J10: BA-RT
A11: Transit | B11: Bus 840 Berchtesgaden → Salzburg (family) | C11: ~€11/pp | D11: 4 | E11: 35 | F11: 52 | G11: 52 | H11: High | I11: Regional bus; not covered by Bayern-Ticket | J11: BA-RT
A12: Transit | B12: Local Berchtesgaden buses (Eagle's Nest + Königssee; 2 days) | C12: ~€8/pp/day | D12: 4 pp × 2 days | E12: 30 | F12: 38 | G12: 38 | H12: High | I12: Berchtesgaden local transit | J12: BA-RT
A13: Activities | B13: Deutsches Museum | C13: €15/adult; €4.50/youth | D13: 2+2 | E13: 30 | F13: 45 | G13: 45 | H13: High | I13: Deutsches Museum official site | J13: BA-AC
... A27: Travel Insurance | B27: Trip protection | C27: $75/pp | D27: 4 | E27: 200 | F27: 300 | G27: 450 | H27: Medium | I27: Standard comprehensive policy | J27: —
A28: TOTAL | E28: =SUM(E2:E27) | F28: =SUM(F2:F27) | G28: =SUM(G2:G27)

Sheet Bavaria2_Costs
A1: Category | B1: Item | C1: Unit Cost | D1: Qty | E1: Low (USD) | F1: Mid (USD) | G1: High (USD) | H1: Confidence | I1: Basis | J1: Source IDs
A2: Flights | B2: IAD→MUC round-trip economy × 4 | C2: $950–1,600/pp | D2: 4 | E2: 3800 | F2: 4800 | G2: 6400 | H2: Medium-High | I2: Same IAD–MUC routing as Option 1; Lufthansa/United nonstop | J2: BA-FL
A3: Bags & Seats | B3: Economy bags + seat selection | C3: $90/pp RT | D3: 4 | E3: 200 | F3: 300 | G3: 450 | H3: Low | I3: Carrier-dependent | J3: BA-FL
A4: Lodging | B4: Munich — 4 nights | C4: $200–450/night | D4: 4 | E4: 800 | F4: 1200 | G4: 1800 | H4: Medium | I4: Same hotel range as Option 1; 2 additional nights | J4: BA-LO
A5: Lodging | B5: Berchtesgaden — 2 nights | C5: $180–450/night | D5: 2 | E5: 360 | F5: 560 | G5: 900 | H5: Medium | I5: Hotel Edelweiss / Vier Jahreszeiten range | J5: BA-LO
A6: Lodging | B6: Salzburg — 3 nights (Festspiele premium applies) | C6: $250–600/night | D6: 3 | E6: 750 | F6: 1125 | G6: 1800 | H6: Medium | I6: 1 additional night vs. Option 1; book 5–6 months ahead | J6: BA-LO
A7: Rail | B7: Bayern-Ticket × 2 days (Neuschwanstein + Munich→Berchtesgaden) | C7: €49/day | D7: 2 days | E7: 110 | F7: 116 | G7: 116 | H7: High | I7: DB Bayern-Ticket; 14yo free; 17yo adult rate | J7: BA-RT
A8: Transit | B8: Munich local transit — non–Bayern-Ticket days (MVV day tickets) | C8: ~$25/family/day | D8: 4 days | E8: 60 | F8: 100 | G8: 100 | H8: High | I8: MVV day tickets; S-Bahn and U-Bahn | J8: BA-RT
A9: Rail | B9: Salzburg → Munich Railjet + seat reservation | C9: ~$35/pp | D9: 4 | E9: 100 | F9: 140 | G9: 200 | H9: High | I9: ÖBB Railjet; book 3–4 weeks ahead | J9: BA-RT
A10: Rail | B10: MUC airport S-Bahn round-trip (2 × family day ticket) | C10: $70/family × 2 | D10: 2 trips | E10: 80 | F10: 140 | G10: 140 | H10: High | I10: MVV airport day ticket | J10: BA-RT
A11: Transit | B11: Bus 840 Berchtesgaden → Salzburg (family) | C11: ~€11/pp | D11: 4 | E11: 35 | F11: 52 | G11: 52 | H11: High | I11: Regional bus; not covered by Bayern-Ticket | J11: BA-RT
A12: Transit | B12: Local Berchtesgaden buses (Eagle's Nest + Königssee; 2 days) | C12: ~€8/pp/day | D12: 4 pp × 2 days | E12: 30 | F12: 38 | G12: 38 | H12: High | I12: Berchtesgaden local transit | J12: BA-RT
A13: Activities | B13: Deutsches Museum | C13: €15/adult; €4.50/youth | D13: 2+2 | E13: 30 | F13: 45 | G13: 45 | H13: High | I13: Deutsches Museum official site | J13: BA-AC
... A26: Travel Insurance | B26: Trip protection | C26: $75/pp | D26: 4 | E26: 200 | F26: 300 | G26: 450 | H26: Medium | I26: Standard comprehensive policy | J26: —
A27: TOTAL | E27: =SUM(E2:E26) | F27: =SUM(F2:F26) | G27: =SUM(G2:G26)

Sheet StLucia_Costs
A1: Category | B1: Item | C1: Unit Cost | D1: Qty | E1: Low (USD) | F1: Mid (USD) | G1: High (USD) | H1: Confidence | I1: Basis | J1: Source IDs | K1: Applies To
A2: Flights | B2: PHL→UVF round-trip economy × 4 (AA nonstop) | C2: $550–1,000/pp | D2: 4 | E2: 2200 | F2: 3000 | G2: 4000 | H2: Medium | I2: AA PHL–UVF weekly nonstop; DC airports add 1 stop + ~$100–150/pp | J2: SL-FL | K2: Both
A3: Bags & Seats | B3: Typical fees | C3: $60/pp RT | D3: 4 | E3: 100 | F3: 240 | G3: 400 | H3: Low | I3: AA nonstop is shorter; fewer fees than connecting | J3: SL-FL | K3: Both
A4: Lodging (A) | B4: Coconut Bay Splash wing — all-inclusive, 10 nights | C4: $650–950/night | D4: 10 nights | E4: 6500 | F4: 7800 | G4: 9500 | H4: Medium | I4: cbayresort.com; 2026 rates TBC; estimate based on historical July AI pricing | J4: SL-LO | K4: Option A only
A5: Lodging (B) | B5: Soufrière villa 2BR with kitchen — 6 nights | C5: $300–450/night | D5: 6 nights | E5: 1800 | F5: 2280 | G5: 2700 | H5: Medium | I5: Stonefield Villa Resort / Fond Doux / private rental (Airbnb/VRBO) | J5: SL-LO | K5: Option B only
A6: Lodging (B) | B6: Bay Gardens Beach Resort, Rodney Bay — 4 nights | C6: $250–380/night | D6: 4 nights | E6: 1000 | F6: 1160 | G6: 1520 | H6: Medium | I6: Bay Gardens direct booking | J6: SL-LO | K6: Option B only
A7: Transfers (A) | B7: UVF → Coconut Bay (free resort shuttle) | C7: $0 | D7: — | E7: 0 | F7: 0 | G7: 0 | H7: High | I7: Coconut Bay direct confirmation | J7: SL-TR | K7: Option A only
A8: Transfers (A) | B8: Excursion day taxis (not resort-included) | C8: Estimate | D8: — | E8: 0 | F8: 120 | G8: 200 | H8: Low | I8: Distance from Vieux Fort adds cost | J8: SL-TR | K8: Option A only
A9: Transfers (B) | B9: UVF → Soufrière (private taxi for 4) | C9: $90–100 | D9: 1 | E9: 90 | F9: 95 | G9: 110 | H9: High | I9: Representative local operator pricing | J9: SL-TR | K9: Option B only
A10: Transfers (B) | B10: Soufrière → Rodney Bay (taxi or water taxi) | C10: $100–180 | D10: 1 | E10: 100 | F10: 130 | G10: 180 | H10: Medium | I10: Water taxi is scenic upgrade; road taxi is practical | J10: SL-TR | K10: Option B only
A11: Transfers (B) | B11: Rodney Bay → UVF (departure) | C11: $100–130 | D11: 1 | E11: 100 | F11: 115 | G11: 130 | H11: High | I11: Representative local operator pricing | J11: SL-TR | K11: Option B only
A12: Transfers (B) | B12: Local taxis throughout trip | C12: Estimate | D12: — | E12: 200 | F12: 300 | G12: 450 | H12: Low | I12: Island roads require taxis; no public transit grid | J12: SL-TR | K12: Option B only
A13: Activities | B13: Gros Piton hike (trail fee + mandatory guide) | C13: $50/pp | D13: 4 | E13: 200 | F13: 215 | G13: 240 | H13: High | I13: St. Lucia National Trust; guide required by law | J13: SL-AC | K13: Both
... A25: Travel Insurance | B25: Hurricane/CFAR policy (strongly recommended for July) | C25: $100/pp | D25: 4 | E25: 300 | F25: 450 | G25: 600 | H25: Medium | I25: July = hurricane season; St. Lucia Holiday Guarantee also available | J25: — | K25: Both
A26: TOTAL — Option A (Coconut Bay All-Inclusive) | E26: =SUMIF($K$2:$K$25,"Both",E2:E25)+SUMIF($K$2:$K$25,"Option A only",E2:E25) | F26: =SUMIF($K$2:$K$25,"Both",F2:F25)+SUMIF($K$2:$K$25,"Option A only",F2:F25) | G26: =SUMIF($K$2:$K$25,"Both",G2:G25)+SUMIF($K$2:$K$25,"Option A only",G2:G25) | K26: A
A27: TOTAL — Option B (Villa + Bay Gardens) | E27: =SUMIF($K$2:$K$25,"Both",E2:E25)+SUMIF($K$2:$K$25,"Option B only",E2:E25) | F27: =SUMIF($K$2:$K$25,"Both",F2:F25)+SUMIF($K$2:$K$25,"Option B only",F2:F25) | G27: =SUMIF($K$2:$K$25,"Both",G2:G25)+SUMIF($K$2:$K$25,"Option B only",G2:G25) | K27: B

Sheet Greece2_Costs
A1: Category | B1: Item | C1: Unit Cost | D1: Qty | E1: Low (USD) | F1: Mid (USD) | G1: High (USD) | H1: Confidence | I1: Basis | J1: Source IDs
A2: Flights | B2: IAD→ATH round-trip economy × 4 | C2: $1,000–1,600/pp | D2: 4 | E2: 4000 | F2: 5200 | G2: 6400 | H2: Medium | I2: Live IAD–ATH searches May 2026; Aegean/United/Lufthansa range | J2: GR-FL
A3: Bags & Seats | B3: Economy bags + seat selection | C3: $50–140/pp RT | D3: 4 | E3: 200 | F3: 360 | G3: 560 | H3: Low | I3: Carrier-dependent; assume 1 checked bag/pp | J3: GR-FL
A4: Domestic Flight | B4: Athens → Chania (ATH→CHQ; Aegean Airlines) | C4: $70–120/pp | D4: 4 | E4: 280 | F4: 380 | G4: 480 | H4: High | I4: Aegean Airlines; book 2–3 months ahead | J4: GR2-DO
A5: Domestic Flight | B5: Heraklion → Athens (HER→ATH; Aegean Airlines) | C5: $70–120/pp | D5: 4 | E5: 280 | F5: 380 | G5: 480 | H5: High | I5: Aegean Airlines; book 2–3 months ahead | J5: GR2-DO
A6: Lodging | B6: West Crete (Agia Marina/Stalos/Kalamaki) — 5 nights | C6: $180–280/night | D6: 5 | E6: 900 | F6: 1150 | G6: 1400 | H6: Medium | I6: Booking.com; beach-area family hotels with pool and parking | J6: GR2-LO
A7: Lodging | B7: East Crete — Agios Nikolaos mid-tier — 3 nights | C7: $150–260/night | D7: 3 | E7: 450 | F7: 660 | G7: 780 | H7: Medium | I7: Mid-tier hotel near harbor; Agios Nikolaos recommended over Elounda for value | J7: GR2-LO
A8: Lodging | B8: Athens — 1 night (Plaka/Koukaki area) | C8: $150–280/night | D8: 1 | E8: 150 | F8: 200 | G8: 280 | H8: Medium | I8: Central Athens hotel; Plaka or Koukaki walkable to Acropolis | J8: GR2-LO
A9: Rental Car | B9: Economy/compact 9 days CHQ pickup → HER return | C9: $50–85/day | D9: 9 | E9: 450 | F9: 580 | G9: 765 | H9: Medium | I9: Budget/Sixt/Europcar Crete; CHQ one-way to HER adds drop fee ~$50–100 | J9: GR2-CA
A10: Fuel & Parking | B10: Crete driving 9 days (~700 km total) | C10: Estimate | D10: — | E10: 150 | F10: 200 | G10: 300 | H10: Low | I10: Crete petrol ~€1.90/L May 2026; minimal tolls; parking €5–10/day in cities | J10: GR2-CA
A11: Activities | B11: Knossos Palace (timed entry) | C11: €15/adult; €8/youth | D11: 4 | E11: 50 | F11: 55 | G11: 55 | H11: High | I11: Greek Ministry of Culture / hhticket.gr | J11: GR2-AC
A12: Activities | B12: Heraklion Archaeological Museum | C12: €15/adult; €8/youth | D12: 4 | E12: 50 | F12: 55 | G12: 55 | H12: High | I12: Official museum site; world-class Minoan collection | J12: GR2-AC
A13: Activities | B13: Acropolis timed entry Day 11 — FIRM | C13: €30/adult; €15/youth | D13: 4 | E13: 120 | F13: 170 | G13: 170 | H13: High | I13: hhticket.gr; book immediately — July 7:30 am slots sell out | J13: GR2-AC
... A20: Travel Insurance | B20: Trip protection (rental car + flight delays) | C20: $80/pp | D20: 4 | E20: 200 | F20: 320 | G20: 500 | H20: Medium | I20: Recommended; ensure rental car coverage included | J20: —
A21: TOTAL | E21: =SUM(E2:E20) | F21: =SUM(F2:F20) | G21: =SUM(G2:G20)

Sheet Cost_Comparison
A1: Category (Mid-Range) | B1: Greece — Opt 1 (Cyclades) | C1: Greece — Opt 2 (Crete) | D1: Bavaria — Opt 1 (Alpine) | E1: Bavaria — Opt 2 (Cities) | F1: St. Lucia (A) All-Incl. | G1: St. Lucia (B) Independent
A2: Flights + Bags | B2: =SUM(Greece_Costs!F2:F3) | C2: =SUM(Greece2_Costs!F2:F5) | D2: =SUM(Bavaria_Costs!F2:F3) | E2: =SUM(Bavaria2_Costs!F2:F3) | F2: =SUM(StLucia_Costs!F2:F3) | G2: =SUM(StLucia_Costs!F2:F3)
A3: Lodging | B3: =SUM(Greece_Costs!F4:F7) | C3: =SUM(Greece2_Costs!F6:F8) | D3: =SUM(Bavaria_Costs!F4:F7) | E3: =SUM(Bavaria2_Costs!F4:F6) | F3: =StLucia_Costs!F4 | G3: =SUM(StLucia_Costs!F5:F6)
A4: Ground Transport / Ferries / Rail | B4: =SUM(Greece_Costs!F8:F12) | C4: =SUM(Greece2_Costs!F9:F10) | D4: =SUM(Bavaria_Costs!F8:F12) | E4: =SUM(Bavaria2_Costs!F7:F12) | F4: =SUM(StLucia_Costs!F7:F8) | G4: =SUM(StLucia_Costs!F9:F12)
A5: Activities | B5: =SUM(Greece_Costs!F13:F20) | C5: =SUM(Greece2_Costs!F11:F18) | D5: =SUM(Bavaria_Costs!F13:F25) | E5: =SUM(Bavaria2_Costs!F13:F24) | F5: =SUM(StLucia_Costs!F13:F21) | G5: =SUM(StLucia_Costs!F13:F21)
A6: Food & Dining | B6: =Greece_Costs!F21 | C6: =Greece2_Costs!F19 | D6: =Bavaria_Costs!F26 | E6: =Bavaria2_Costs!F25 | F6: =StLucia_Costs!F22 | G6: =StLucia_Costs!F23
A7: Insurance & Misc | B7: =Greece_Costs!F22 | C7: =Greece2_Costs!F20 | D7: =Bavaria_Costs!F27 | E7: =Bavaria2_Costs!F26 | F7: =SUM(StLucia_Costs!F24:F25) | G7: =SUM(StLucia_Costs!F24:F25)
A8: TOTAL MID (Family of 4) | B8: =SUM(B2:B7) | C8: =SUM(C2:C7) | D8: =SUM(D2:D7) | E8: =SUM(E2:E7) | F8: =SUM(F2:F7) | G8: =SUM(G2:G7)
A9: Nights on Ground | B9: =Summary!C2 | C9: =Summary!C3 | D9: =Summary!C4 | E9: =Summary!C5 | F9: =Summary!C6 | G9: =Summary!C7
A10: Cost per Night on Ground (Mid) | B10: =B8/B9 | C10: =C8/C9 | D10: =D8/D9 | E10: =E8/E9 | F10: =F8/F9 | G10: =G8/G9

Sheet Source_Register
A1: Source ID | B1: Destination | C1: Category | D1: Source Name | E1: URL / Where to Find | F1: What It Supports | G1: Reliability | H1: Notes
A2: GR-FL | B2: Greece Opt 1 | C2: Flights | D2: United Airlines IAD–ATH seasonal nonstop | E2: united.com | F2: IAD–ATH nonstop routing and fare confirmation | G2: High | H2: Seasonal summer nonstop; verify July 2026 schedule
A3: GR-FL | B3: Greece Opt 1 | C3: Flights | D3: Lufthansa IAD–FRA–ATH | E3: lufthansa.com | F3: Connecting option; typically competitive in advance | G3: High
A4: GR-FL | B4: Greece Opt 1 | C4: Flights | D4: Google Flights / Kayak | E4: flights.google.com / kayak.com | F4: Fare market scanning and range validation | G4: Medium | H4: Fares highly volatile; use as range only
A5: GR-AC | B5: Greece Opt 1 | C5: Attractions | D5: Greek Ministry of Culture / hhticket.gr | E5: hhticket.gr | F5: Acropolis timed-entry booking; official pricing (€30 flat 2026) | G5: High | H5: Book timed entry immediately; July slots sell out weeks ahead
A6: GR-AC | B6: Greece Opt 1 | C6: Attractions | D6: Acropolis Museum official | E6: theacropolismuseum.gr | F6: Museum hours; admission pricing (€15 adult) | G6: High
A7: GR-FE | B7: Greece Opt 1 | C7: Ferries | D7: Blue Star Ferries | E7: bluestarferries.com | F7: Piraeus–Naxos schedules; pricing; stability in meltemi winds | G7: High | H7: Blue Star far more wind-stable than Seajets; recommended for Piraeus–Naxos leg
A8: GR-FE | B8: Greece Opt 1 | C8: Ferries | D8: Seajets | E8: seajets.com | F8: Fast-ferry schedules Naxos–Santorini; pricing | G8: High | H8: Weather-sensitive; check before travel
A9: GR-FE | B9: Greece Opt 1 | C9: Ferries | D9: Ferryhopper (aggregator) | E9: ferryhopper.com | F9: Ferry booking aggregator; compares operators | G9: Medium-High | H9: Good for comparing Blue Star vs. Seajets options
A10: GR-DF | B10: Greece Opt 1 | C10: Domestic Flights | D10: Aegean Airlines | E10: aegeanair.com | F10: Santorini → Athens domestic; 5–6 daily; ~50 min | G10: High | H10: Recommended for buffer-day return to Athens
A11: GR-LO | B11: Greece Opt 1 | C11: Lodging | D11: Booking.com / Expedia / direct hotels | E11: booking.com | F11: Athens, Naxos, Santorini family room rates | G11: Medium | H11: July peak; Santorini caldera-view hotels sell out 6+ months ahead
A12: GR-TR | B12: Greece Opt 1 | C12: Transfers | D12: Proastiakos Athens Metro (airport express) | E12: stasy.gr | F12: Athens airport express train; fares; under-18 half price | G12: High
A13: GR-FD | B13: Greece Opt 1 | C13: Food | D13: Greek National Tourism Org / Santorini Dave | E13: visitgreece.gr | F13: Dining cost benchmarks for Athens, Naxos, Santorini | G13: Medium | H13: Estimate; confirm on arrival
A14: GR2-DO | B14: Greece Opt 2 | C14: Domestic Flights | D14: Aegean Airlines ATH–CHQ / HER–ATH | E14: aegeanair.com | F14: Both Crete domestic legs; ~50 min each; book 2–3 months ahead | G14: High | H14: Book together with main IAD–ATH international itinerary
A15: GR2-LO | B15: Greece Opt 2 | C15: Lodging | D15: Booking.com / direct Crete hotels | E15: booking.com | F15: West Crete (Agia Marina/Stalos) and East Crete (Agios Nikolaos) family hotel rates | G15: Medium | H15: Book Agios Nikolaos mid-tier hotel 4–5 months ahead for July
A16: GR2-CA | B16: Greece Opt 2 | C16: Car Rental | D16: Budget / Sixt / Europcar Crete | E16: budget.com / sixt.com | F16: Economy/compact rental CHQ pickup one-way to HER; 9 days | G16: Medium | H16: One-way drop fee varies; compare operators directly; fuel full-to-full
A17: GR2-AC | B17: Greece Opt 2 | C17: Attractions | D17: Greek Ministry of Culture / hhticket.gr — Knossos & Heraklion Museum | E17: hhticket.gr | F17: Knossos Palace timed entry and Heraklion Archaeological Museum pricing | G17: High | H17: Knossos timed entry recommended in July; museum is world-class
A18: GR2-AC | B18: Greece Opt 2 | C18: Attractions | D18: hhticket.gr — Acropolis timed entry | E18: hhticket.gr | F18: Acropolis Day 11 firm activity; €30 adult flat rate 2026 | G18: High | H18: Book immediately; July 7:30 am slots sell out weeks ahead
A19: GR2-AC | B19: Greece Opt 2 | C19: Attractions | D19: Elounda–Spinalonga local boat operators | E19: elounda.gr / local dock | F19: Spinalonga round-trip boat and island entry; morning boats recommended | G19: High | H19: Multiple operators at Elounda dock; pre-book July
A20: GR2-AC | B20: Greece Opt 2 | C20: Attractions | D20: Kissamos Ferry (Balos Lagoon) | E20: kissamos-ferries.gr | F20: Kissamos–Balos return ferry; seasonal May–Oct; July books up | G20: Medium | H20: Pre-book ferry; alternatively drive to Balos overlook for free
A21: GR2-FD | B21: Greece Opt 2 | C21: Food | D21: Crete dining benchmarks | E21: visitcrete.gr / local restaurant guides | F21: Cretan taverna food cost benchmarks; Agios Nikolaos harbor restaurants | G21: Medium | H21: Crete generally good value vs. Santorini; harbor slightly premium
A22: BA-FL | B22: Bavaria | C22: Flights | D22: Lufthansa IAD–MUC nonstop | E22: lufthansa.com | F22: Direct nonstop service; ~8h 10m | G22: High | H22: Also check United IAD–MUC
A23: BA-FL | B23: Bavaria | C23: Flights | D23: Icelandair via KEF | E23: icelandair.com | F23: Budget routing option; adds ~2–3 hrs | G23: Medium | H23: Good for low scenario pricing
A24: BA-RT | B24: Bavaria | C24: Rail | D24: Deutsche Bahn Bayern-Ticket | E24: bahn.de | F24: Bayern-Ticket pricing; validity; free-child rule (ages 6–14 free) | G24: High | H24: 14yo rides free; 17yo is adult rate; €49/family of 4 per day
... A29: BA-AC | B29: Bavaria | C29: Attractions | D29: Kehlstein (Eagle's Nest) | E29: kehlsteinhaus.de | F29: Bus/elevator access; seasonal operation; ticket pricing | G29: High | H29: Cash/credit card at top; operates May–Oct
A30: BA-AC | B30: Bavaria | C30: Attractions | D30: Deutsches Museum | E30: deutsches-museum.de | F30: Admission pricing; hours; teen-appeal content | G30: High
A31: BA-AC | B31: Bavaria | C31: Attractions | D31: Festung Hohensalzburg | E31: salzburg-burgen.at | F31: Fortress funicular pricing; adult/youth rates | G31: High
A32: BA-LO | B32: Bavaria | C32: Lodging | D32: Booking.com / direct hotels | E32: booking.com | F32: Munich / Mittenwald / Berchtesgaden / Salzburg family room rates | G32: Medium | H32: Salzburg: book 5–6 months ahead due to Festspiele
A33: BA-FD | B33: Bavaria | C33: Food | D33: Munich / Bavaria general tourism | E33: munich.travel | F33: Food cost benchmarks; beer garden pricing | G33: Medium | H33: Bavaria moderately priced; bakery + beer garden strategy keeps costs low
A34: BA2-AC | B34: Bavaria Opt 2 | C34: Attractions | D34: Neuschwanstein / Hohenschwangau official tickets | E34: tickets.hohenschwangau.de | F34: Neuschwanstein timed interior tour; under 18 free with guardian; July availability | G34: High | H34: Book immediately upon confirming trip; July sells out weeks ahead
A35: BA2-AC | B35: Bavaria Opt 2 | C35: Attractions | D35: Schloss Nymphenburg official | E35: schloss-nymphenburg.de | F35: Palace entry pricing; grounds and canals free; summer café on-site | G35: High | H35: Good half-day activity; grounds free even without palace entry
A36: BA2-AC | B36: Bavaria Opt 2 | C36: Attractions | D36: Hallstatt tourism / ÖBB regional rail | E36: hallstatt.net / oebb.at | F36: Hallstatt day trip logistics from Salzburg; train + bus combo; Salzwelten mine museum | G36: Medium | H36: Regional rail Salzburg–Attnang-Puchheim–Hallstatt; arrive early to beat July tour buses
A37: SL-FL | B37: St. Lucia | C37: Flights | D37: American Airlines PHL–UVF | E37: aa.com | F37: Weekly nonstop PHL–UVF; ~4h 45m; fare range | G37: High | H37: Verify exact July 2026 schedule; check early for PHL nonstop availability
A38: SL-LO | B38: St. Lucia | C38: Lodging | D38: Coconut Bay Resort | E38: cbayresort.com | F38: All-inclusive family Splash wing; rates; inclusions | G38: Medium | H38: 2026 July rates not yet published; get direct quote
A39: SL-LO | B39: St. Lucia | C39: Lodging | D39: Bay Gardens Beach Resort | E39: baygardensresorts.com | F39: Rodney Bay family rooms; nightly rates | G39: High
A40: SL-LO | B40: St. Lucia | C40: Lodging | D40: Stonefield Villa Resort | E40: stonefieldvillas.com | F40: Soufrière villa option; 2BR; Piton views | G40: High
A41: SL-AC | B41: St. Lucia | C41: Activities | D41: St. Lucia National Trust (Gros Piton) | E41: slunatrust.org | F41: Gros Piton trail fee ($50/pp); mandatory guide requirement | G41: High | H41: Guide is legally required; adds real value
A42: SL-AC | B42: St. Lucia | C42: Activities | D42: Tet Paul Nature Trail | E42: thetetpaulnaturetrail.com | F42: Entry pricing; trail description; panoramic Piton views | G42: High
A43: SL-AC | B43: St. Lucia | C43: Activities | D43: Sea Spray Cruises | E43: seaspreystlucia.com | F43: Tout Bagay full-day catamaran; pricing; schedule | G43: High
A44: SL-AC | B44: St. Lucia | C44: Activities | D44: Rainforest Adventures St. Lucia | E44: rainforestadventure.com | F44: Aerial tram + zip-line; pricing; age/weight requirements | G44: High | H44: Min age 8; max 290 lbs
...
